Workbook

Sheet Тест_в1
B1: Цель теста- оценить собственное восприятие стиля человекоцентричности через фокус на людей или на задачи. Другими словами, через какой стиль лидер проявляет свою человекоцентричность-через поддержку и развитие людей или через эффективное решение задач.
B2: Как работать с тестом? Вам будет предложено 12 блоков рабочих ситуаций. В каждой из ситуаций задача распределить 6 или 7 баллов - что больше похоже ваше поведение как лидера. Если вы согласны с утверждением на все 100% вы можете отдать ему все 7 баллов. Проверьте, чтобы сумма баллов по каждому блоку не превышала 7.
B3: Рекомендации по заполнению:
B4: Инструмент был разработан на основе модели человекоцентричного лидерства в Ростелекоме.
B5: Тест
A6: 1. | B6: Клиент (заказчик) выражает сомнения в выборе предложенного вами решения, предлагая альтернативный подход. Какое действие, по-вашему мнению, будет наиболее правильным? | D6: К (клиент) | E6: с Аней (распределить 7 баллов)?
A7: a
A8: b
A9: c
A10: d
A11: 2. | B11: Подчиненный только что присоединился к команде и испытывает трудности с пониманием процессов. На чем, по-вашему мнению, надо сфокусироваться в процессе его адаптации? | D11: П (подчиненный)
A12: a
A13: b
A14: c
A15: d
A16: 3. | B16: Коллега просит вашего мнения по своему проекту, чтобы избежать ошибок. Какой вариант действия вы считаете наиболее правильным в данной ситуации? | D16: Кл (коллега)
A17: a
A18: b
A19: c
A20: d
A21: 4. | B21: Руководитель предлагает вам возглавить новый проект. На каких вопросах вы считаете правильным сосредоточиться прежде всего? | D21: Р (руководитель)
A22: a
A23: b
A24: c
A25: d
A26: 5. | B26: Заказчик просит провести обучающий семинар для его команды, чтобы лучше понять ваш продукт\услуги. Какое действие, по-вашему мнению, будет наиболее правильным? | D26: К (клиент)
A27: a
A28: b
A29: c
A30: d
A31: 6. | B31: Вы запланировали мотивационную беседу с эффективным сотрудником. На чем вы считаете правильным сделать акцент во время вашей встречи? | D31: П (подчиненный)
A32: a
A33: b
A34: c
A35: d
A36: 7. | B36: Коллега делится новыми идеями для улучшения процесса. Какой вариант действия вы считаете наиболее правильным в этой ситуации? | D36: Кл (коллега)
A37: a
A38: b
A39: c
A40: d
...

Sheet Тест_в2
B1: Введение Этот тест поможет определить ваш ведущий стиль человекоцентричного лидерства — индивидуального подхода, который вы используете для создания осмысленной, доброжелательной и продуктивной рабочей среды. Человекоцентричное лидерство — управленческий подход, при котором лидер создаёт ценность для организации через осмысленную заботу о людях: сотрудниках, коллегах, клиентах и партнёрах. Каждый лидер проявляет человекоцентричность через один из четырех стилей, соответствующих четырем векторам модели: Культура, Лидер, Процессы и практики, Стратегия. Тест раскрывает уникальность вашего стиля, его особенности, и не направлен на оценку уровня\индекса человекоцентричности. Прохождение теста позволит вам: - Узнать, какой стиль человекоцентричного лидерства вам ближе всего и как он проявляется в вашей работе. - Понять, в каких ситуациях ваш стиль наиболее эффективен, а где стоит использовать другие подходы. - Получить практические рекомендации по развитию вашего стиля для усиления влияния на команду и организацию. По завершению теста вы сможете ознакомиться со своим персональным отчетом. Тест разработан на основе: -Модели человекоцентричного лидерства в Ростелекоме -Классической модели Р.Лайкерта , объединяющую "Фокус на людей"- "Фокус на задачи" -Теории цикла командного взаимодействия | D1: может быть где-то на портале разместить модель ЧЛ и дать на нее ссылку? | E1: мне тоже понравилась идея разместить модель ЧЛ т.к. читая описание стоит акцент именно на человекоцентр лидерстве и прям хочется задать вопрос что это? В чем отличие от лидерства? Что за методология.
B2: Как работать с тестом? Вам будет предложено 14 блоков. В каждом из блоков распределите 7 баллов между 4 вариантами. Каждому из вариантов можно присвоить от 0 до 7 баллов. Чем больше баллов вы присваиваете варианту, тем точнее он описывает ваше обычное поведение. Одному утверждению можно отдать все 7 баллов. | D2: для проектной команды: 14 блоков- по 2 вопроса на каждый блок из цикла командного взаимодействия (7*2), чтобы обеспечить вариантивность и точнее определить ведущий стиль. | E2: Поскольку стилей всего 4, выводить 2 ведущих не хотелось бы. Дополнительное ограничение "минимум 2 балла" позволит более четко выделить ведущий стиль?
B3: Рекомендации по заполнению: Следите за подсказками, они помогут верно распределить баллы. Если какой-то из блоков бует пропущен или превышено\не хватает баллов по блоку, система предложит к нему вернуться. В конце теста вы получите отчет, в котором будет информация о вашем ведущем стиле человекоцентричного лидерства- его особенностях и рекомендации по усилению. Также с помощью отчета сможете ознакомиться с другими стилями. Обратите внимание, в тесте нет правильных или неправильных вариантов. Постарайтесь отвечать открыто и честно, не раздумывая долго. Тест не ограничен по времени.
B5: Опирайся на цикл командного взаимодействия | D5: это только для проектной команды по опроснику: в основе создания блоков с вопросами полный цикл командного взаимодействия
B7: Тест | C7: Распределите 7 баллов между 4 вариантами. Каждому из вариантов можно присвоить от 0 до 7 баллов. Чем больше баллов вы присваиваете варианту, тем точнее он описывает ваше обычное поведение. Одному утверждению можно отдать все 7 баллов. | D7: При заполнении пользователем ячейки с баллами, подсвечивается кол-во оставшихся баллов из 7. Если все 7 баллов использованы – всплывает сообщение «Вы использовали все баллы». | E7: Ключ для проектной команды (перемешиваем варианты, чтобы снизить очевидность)
B8: блок 1/1 вклад в команду (что я привношу) | D8: для проектной команды, не выводим для пользователя
A9: 1 | B9: Какова ваша ценность для команды? | D9: =IF(SUM(C10:C13)>7, "Вы использовали все баллы", IF(SUM(C10:C13)<7, "Вы использовали не все баллы", ""))
A10: a | B10: Я задаю амбициозные цели и помогаю команде создавать результат, приносящий ценность клиенту и обществу | C10: 3 | D10: ="Осталось: "&7-SUM(C10:C13)&" из 7" -> Осталось: 0 из 7 | E10: Целеустремленный
A11: b | B11: Я создаю и поддерживаю в команде атмосферу взаимопомощи, уважения и доброжелательного общения | C11: 1 | E11: Командный
A12: c | B12: Я создаю условия для развития и раскрытия потенциала сотрудников, воодушевляя личным примером | C12: 1 | E12: Вдохновляющий
A13: d | B13: Я выстраиваю понятные договорённости и прозрачную организацию работы, убирая барьеры в процессах | C13: 2 | E13: Процессный
B14: блок 2\1 (мои ограничения как члена команды, теневая сторона) | D14: для проектной команды, не выводим для пользователя
A15: 2 | B15: Каковы ваши недостатки как лидера? | D15: =IF(SUM(C16:C19)>7, "Вы использовали все баллы", IF(SUM(C16:C19)<7, "Вы использовали не все баллы", ""))
A16: a | B16: Я могу настаивать на соблюдении договорённостей и ясности правил, даже когда ситуация требует гибкости | C16: 5 | D16: ="Осталось: "&7-SUM(C16:C19)&" из 7" -> Осталось: 0 из 7 | E16: Процессный
A17: b | B17: Я могу быть требовательным к срокам и результатам для клиента и компании, уделяя недостаточно внимания состоянию подчиненных | E17: Целеустремленный
A18: c | B18: Я могу тратить много времени на создание отношений в команде и откладывать трудные, непопулярные решения | E18: Командный
A19: d | B19: Я могу быть настолько увлечён развитием людей и вдохновением, что упускаю контроль результатов | C19: 2 | E19: Вдохновляющий
B20: блок 3\1 (работа с другими, стиль взаимодействия) | D20: для проектной команды, не выводим для пользователя
A21: 3 | B21: Какую роль обычно берете на себя при обсуждении совместных задач? | D21: =IF(SUM(C22:C25)>7, "Вы использовали все баллы", IF(SUM(C22:C25)<7, "Вы использовали не все баллы", ""))
A22: a | B22: Я помогаю услышать друг друга, открыто обменяться мнениями, договориться о совместной работе | D22: ="Осталось: "&7-SUM(C22:C25)&" из 7" -> Осталось: 0 из 7 | E22: Командный
A23: b | B23: Я транслирую связь задач с ценностью для клиента и общества, помогая команде прийти к лучшему результату | C23: 2 | E23: Целеустремленный
A24: c | B24: Я объясняю, как устроена работа, чтобы каждый понимал свою роль, договорённости и следующий шаг | C24: 5 | E24: Процессный
A25: d | B25: Я помогаю людям увидеть смысл задачи, возможности для роста и поверить в свой потенциал | E25: Вдохновляющий
B26: блок 4\1 (отношение к задачам, как я подхожу к работе) | D26: для проектной команды, не выводим для пользователя
A27: 4 | B27: Каковы особенности вашего лидерского стиля в рабочем процессе? | D27: =IF(SUM(C28:C31)>7, "Вы использовали все баллы", IF(SUM(C28:C31)<7, "Вы использовали не все баллы", ""))
A28: a | B28: Я задаю пример стремления к развитию и создаю условия для освоения нового | C28: 3 | D28: ="Осталось: "&7-SUM(C28:C31)&" из 7" -> Осталось: 0 из 7 | E28: Вдохновляющий
A29: b | B29: Я систематизирую задачи, выстраиваю четкие алгоритмы и регламенты для их выполнения | C29: 4 | E29: Процессный
A30: c | B30: Я контролирую ключевые показатели, четко слежу за достижением результата | E30: Целеустремленный
A31: d | B31: Я распределяю задачи, чтобы каждый чувствовал свою значимость, и поощряю взаимовыручку в команде | E31: Командный
B32: блок 5\1 (личное удовлетворение, что мне нравится в работе) | D32: для проектной команды, не выводим для пользователя
A33: 5 | B33: Что вдохновляет вас как лидера? | D33: =IF(SUM(C34:C37)>7, "Вы использовали все баллы", IF(SUM(C34:C37)<7, "Вы использовали не все баллы", ""))
A34: a | B34: Видеть, что в команде вежливо общаются и готовы помогать друг другу | C34: 4 | D34: ="Осталось: "&7-SUM(C34:C37)&" из 7" -> Осталось: 0 из 7 | E34: Командный
A35: b | B35: Замечать, что люди раскрывают потенциал, осваивают новое и берутся за развивающие задачи | E35: Вдохновляющий
A36: c | B36: Видеть, как отлаженная мною система работает как часы | C36: 3 | E36: Процессный
A37: d | B37: Достигать невозможные, на первый взгляд, результаты для клиентов и заказчиков | E37: Целеустремленный
B38: блок 6\1 (отношение к другим, коллаборация) | D38: для проектной команды, не выводим для пользователя
A39: 6 | B39: Каков ваш вклад в развитие идей коллег? | D39: =IF(SUM(C40:C43)>7, "Вы использовали все баллы", IF(SUM(C40:C43)<7, "Вы использовали не все баллы", ""))
A40: a | B40: Я продвигаю идеи коллег, создавая для них возможности развития | C40: 4 | D40: ="Осталось: "&7-SUM(C40:C43)&" из 7" -> Осталось: 0 из 7 | E40: Вдохновляющий
A41: b | B41: Я проверяю идеи на соответствие принятым стандартам и реализуемость | E41: Процессный
A42: c | B42: Я помогаю оценить идеи по их вкладу в прибыль\KPI и пользу для Общества | C42: 3 | E42: Целеустремленный
...

Sheet Механика подсчета результатов
A1: Перемешиваем варианты ответов | J1: Таблица подсчета результатов | K1: Целеустремленный | L1: Вдохновляющий | M1: Командный | N1: Процессный | O1: проверка | R1: Целеустремленный | S1: Вдохновляющий | T1: Командный | U1: Процессный | V1: StyleIdx
A2: блоки | B2: 1 | C2: A | D2: C | E2: B | F2: D | H2: А- «Целеустременный» | J2: 1 | K2: =IFERROR(VALUE(INDEX(Тест_в2!C10:C13, MATCH("A", C2:F2, 0))), 0) -> 3 | L2: =IFERROR(VALUE(INDEX(Тест_в2!C10:C13, MATCH("B", C2:F2, 0))), 0) -> 1 | M2: =IFERROR(VALUE(INDEX(Тест_в2!C10:C13, MATCH("C", C2:F2, 0))), 0) -> 1 | N2: =IFERROR(VALUE(INDEX(Тест_в2!C10:C13, MATCH("D", C2:F2, 0))), 0) -> 2 | O2: =SUM(K2:N2) -> 7 | R2: =K16 -> 34 | S2: =L16 -> 16 | T2: =M16 -> 14 | U2: =N16 -> 34 | V2: =MATCH(MAX(R2:U2), R2:U2, 0) -> 1
B3: 2 | C3: D | D3: A | E3: C | F3: B | H3: В- «Вдохновлящий» | J3: 2 | K3: =IFERROR(VALUE(INDEX(Тест_в2!C16:C19, MATCH("A", C3:F3, 0))), 0) -> 0 | L3: =IFERROR(VALUE(INDEX(Тест_в2!C16:C19, MATCH("B", C3:F3, 0))), 0) -> 2 | M3: =IFERROR(VALUE(INDEX(Тест_в2!C16:C19, MATCH("C", C3:F3, 0))), 0) -> 0 | N3: =IFERROR(VALUE(INDEX(Тест_в2!C16:C19, MATCH("D", C3:F3, 0))), 0) -> 5 | O3: =SUM(K3:N3) -> 7
B4: 3 | C4: C | D4: A | E4: D | F4: B | H4: С- «Командый» | J4: 3 | K4: =IFERROR(VALUE(INDEX(Тест_в2!C22:C25, MATCH("A", C4:F4, 0))), 0) -> 2 | L4: =IFERROR(VALUE(INDEX(Тест_в2!C22:C25, MATCH("B", C4:F4, 0))), 0) -> 0 | M4: =IFERROR(VALUE(INDEX(Тест_в2!C22:C25, MATCH("C", C4:F4, 0))), 0) -> 0 | N4: =IFERROR(VALUE(INDEX(Тест_в2!C22:C25, MATCH("D", C4:F4, 0))), 0) -> 5 | O4: =SUM(K4:N4) -> 7
B5: 4 | C5: B | D5: D | E5: A | F5: C | H5: D- «Процессный» | J5: 4 | K5: =IFERROR(VALUE(INDEX(Тест_в2!C28:C31, MATCH("A", C5:F5, 0))), 0) -> 0 | L5: =IFERROR(VALUE(INDEX(Тест_в2!C28:C31, MATCH("B", C5:F5, 0))), 0) -> 3 | M5: =IFERROR(VALUE(INDEX(Тест_в2!C28:C31, MATCH("C", C5:F5, 0))), 0) -> 0 | N5: =IFERROR(VALUE(INDEX(Тест_в2!C28:C31, MATCH("D", C5:F5, 0))), 0) -> 4 | O5: =SUM(K5:N5) -> 7
B6: 5 | C6: C | D6: B | E6: D | F6: A | J6: 5 | K6: =IFERROR(VALUE(INDEX(Тест_в2!C34:C37, MATCH("A", C6:F6, 0))), 0) -> 0 | L6: =IFERROR(VALUE(INDEX(Тест_в2!C34:C37, MATCH("B", C6:F6, 0))), 0) -> 0 | M6: =IFERROR(VALUE(INDEX(Тест_в2!C34:C37, MATCH("C", C6:F6, 0))), 0) -> 4 | N6: =IFERROR(VALUE(INDEX(Тест_в2!C34:C37, MATCH("D", C6:F6, 0))), 0) -> 3 | O6: =SUM(K6:N6) -> 7
B7: 6 | C7: B | D7: D | E7: A | F7: C | J7: 6 | K7: =IFERROR(VALUE(INDEX(Тест_в2!C40:C43, MATCH("A", C7:F7, 0))), 0) -> 3 | L7: =IFERROR(VALUE(INDEX(Тест_в2!C40:C43, MATCH("B", C7:F7, 0))), 0) -> 4 | M7: =IFERROR(VALUE(INDEX(Тест_в2!C40:C43, MATCH("C", C7:F7, 0))), 0) -> 0 | N7: =IFERROR(VALUE(INDEX(Тест_в2!C40:C43, MATCH("D", C7:F7, 0))), 0) -> 0 | O7: =SUM(K7:N7) -> 7
B8: 7 | C8: A | D8: C | E8: B | F8: D | J8: 7 | K8: =IFERROR(VALUE(INDEX(Тест_в2!C46:C49, MATCH("A", C8:F8, 0))), 0) -> 7 | L8: =IFERROR(VALUE(INDEX(Тест_в2!C46:C49, MATCH("B", C8:F8, 0))), 0) -> 0 | M8: =IFERROR(VALUE(INDEX(Тест_в2!C46:C49, MATCH("C", C8:F8, 0))), 0) -> 0 | N8: =IFERROR(VALUE(INDEX(Тест_в2!C46:C49, MATCH("D", C8:F8, 0))), 0) -> 0 | O8: =SUM(K8:N8) -> 7
B9: 8 | C9: C | D9: B | E9: D | F9: A | J9: 8 | K9: =IFERROR(VALUE(INDEX(Тест_в2!C52:C55, MATCH("A", C9:F9, 0))), 0) -> 7 | L9: =IFERROR(VALUE(INDEX(Тест_в2!C52:C55, MATCH("B", C9:F9, 0))), 0) -> 0 | M9: =IFERROR(VALUE(INDEX(Тест_в2!C52:C55, MATCH("C", C9:F9, 0))), 0) -> 0 | N9: =IFERROR(VALUE(INDEX(Тест_в2!C52:C55, MATCH("D", C9:F9, 0))), 0) -> 0 | O9: =SUM(K9:N9) -> 7
B10: 9 | C10: C | D10: B | E10: D | F10: A | J10: 9 | K10: =IFERROR(VALUE(INDEX(Тест_в2!C58:C61, MATCH("A", C10:F10, 0))), 0) -> 0 | L10: =IFERROR(VALUE(INDEX(Тест_в2!C58:C61, MATCH("B", C10:F10, 0))), 0) -> 0 | M10: =IFERROR(VALUE(INDEX(Тест_в2!C58:C61, MATCH("C", C10:F10, 0))), 0) -> 3 | N10: =IFERROR(VALUE(INDEX(Тест_в2!C58:C61, MATCH("D", C10:F10, 0))), 0) -> 4 | O10: =SUM(K10:N10) -> 7
B11: 10 | C11: B | D11: D | E11: A | F11: C | J11: 10 | K11: =IFERROR(VALUE(INDEX(Тест_в2!C64:C67, MATCH("A", C11:F11, 0))), 0) -> 3 | L11: =IFERROR(VALUE(INDEX(Тест_в2!C64:C67, MATCH("B", C11:F11, 0))), 0) -> 0 | M11: =IFERROR(VALUE(INDEX(Тест_в2!C64:C67, MATCH("C", C11:F11, 0))), 0) -> 0 | N11: =IFERROR(VALUE(INDEX(Тест_в2!C64:C67, MATCH("D", C11:F11, 0))), 0) -> 4 | O11: =SUM(K11:N11) -> 7
B12: 11 | C12: A | D12: C | E12: B | F12: D | J12: 11 | K12: =IFERROR(VALUE(INDEX(Тест_в2!C70:C73, MATCH("A", C12:F12, 0))), 0) -> 2 | L12: =IFERROR(VALUE(INDEX(Тест_в2!C70:C73, MATCH("B", C12:F12, 0))), 0) -> 3 | M12: =IFERROR(VALUE(INDEX(Тест_в2!C70:C73, MATCH("C", C12:F12, 0))), 0) -> 2 | N12: =IFERROR(VALUE(INDEX(Тест_в2!C70:C73, MATCH("D", C12:F12, 0))), 0) -> 0 | O12: =SUM(K12:N12) -> 7
B13: 12 | C13: C | D13: A | E13: D | F13: B | J13: 12 | K13: =IFERROR(VALUE(INDEX(Тест_в2!C76:C79, MATCH("A", C13:F13, 0))), 0) -> 3 | L13: =IFERROR(VALUE(INDEX(Тест_в2!C76:C79, MATCH("B", C13:F13, 0))), 0) -> 0 | M13: =IFERROR(VALUE(INDEX(Тест_в2!C76:C79, MATCH("C", C13:F13, 0))), 0) -> 4 | N13: =IFERROR(VALUE(INDEX(Тест_в2!C76:C79, MATCH("D", C13:F13, 0))), 0) -> 0 | O13: =SUM(K13:N13) -> 7
B14: 13 | C14: D | D14: A | E14: C | F14: B | J14: 13 | K14: =IFERROR(VALUE(INDEX(Тест_в2!C82:C85, MATCH("A", C14:F14, 0))), 0) -> 0 | L14: =IFERROR(VALUE(INDEX(Тест_в2!C82:C85, MATCH("B", C14:F14, 0))), 0) -> 0 | M14: =IFERROR(VALUE(INDEX(Тест_в2!C82:C85, MATCH("C", C14:F14, 0))), 0) -> 0 | N14: =IFERROR(VALUE(INDEX(Тест_в2!C82:C85, MATCH("D", C14:F14, 0))), 0) -> 7 | O14: =SUM(K14:N14) -> 7
B15: 14 | C15: B | D15: D | E15: A | F15: C | J15: 14 | K15: =IFERROR(VALUE(INDEX(Тест_в2!C88:C91, MATCH("A", C15:F15, 0))), 0) -> 4 | L15: =IFERROR(VALUE(INDEX(Тест_в2!C88:C91, MATCH("B", C15:F15, 0))), 0) -> 3 | M15: =IFERROR(VALUE(INDEX(Тест_в2!C88:C91, MATCH("C", C15:F15, 0))), 0) -> 0 | N15: =IFERROR(VALUE(INDEX(Тест_в2!C88:C91, MATCH("D", C15:F15, 0))), 0) -> 0 | O15: =SUM(K15:N15) -> 7
J16: Сумма баллов по стилю | K16: =SUM(K2:K15) -> 34 | L16: =SUM(L2:L15) -> 16 | M16: =SUM(M2:M15) -> 14 | N16: =SUM(N2:N15) -> 34 | O16: =SUM(K16:N16) -> 98
K18: максимальное кол-во баллов, к-ое можно набрать по одному стилю и вообще -98
R20: Ведущий стиль: | S20: =INDEX(R1:U1, MATCH(MAX(R2:U2), R2:U2, 0)) -> Целеустремленный
M21: =LARGE(R2:U2, 2) -> 34 | S21: =MAX(R2:U2) -> 34
R22: Второй близкий стиль (если разница <=5): | S22: =IF(S21-M21<=5, INDEX(R1:U1, MATCH(M21, R2:U2, 0)), "") -> Целеустремленный
R23: Разница баллов: | S23: =IF(S22="", "", S21-M21) -> 0

Sheet 1. Вводная часть отчета
A1: Об отчете
A2: Поздравляем вас с завершением теста! Теперь можно познакомиться с результатами. Данный отчет отображает результаты, полученные при прохождении теста. Тест предназначен для определения ведущего стиля, с помощью которого вы проявляете человеокцентричность. Цель отчета- выявить ваш наиболее предпочитаемый стиль и дать рекомендации по усилению человекоцентричной культуры в вашей команде. Персональный отчет состоит из нескольких блоков: -Введение -Ваши результаты -Характеристика других стилей -Рекомендации по развитию вашего стиля человекоцентричного лидерства
A3: Об инструменте
A4: Инструмент диагностики "Тест на определение ведущего стиля человекоцентричного лидерства" создан на основе: - Модели "Человекоцентричного лидерства в Ростелекоме", - Модели Р.Лайкерта "Фокус на людей"- "Фокус на задачи", - Теории цикла командного взаимодействия. Что такое человекоцентричное лидерство? - Это подход в управлении, где центром является человек: клиент, подчиненный, коллега, руководитель-все, с кем взаимодействует лидер в организации. Модель ЧЛ опирается на четыре вектора: Культура, Лидер, Процессы и практики, Стратегия. Каждому вектору соответствует определенный стиль. Важно: данный тест не направлен на выявление целегового или желательного уровня\индекса человекоцентричности. Он способствует понимаю лидера особенностей своего стиля, а также ситуаций, в которых данный стиль будет предпочтителен, а где стоит применять другие подходы.

Sheet 2. Харак-ка стилей
A2: Стиль "Целеустремленный"
A3: Характеристика: Данный стиль ориентирован на результат и создание ценности для клиентов. Вектор в модели человекоцентричности- Стратегия. Приоритеты — цели, достижения, своевременные решения, создание ценности для клиента и общества. Целеустремлённый лидер проявляет человекоцентричность через ясность целей и достижение результата, который приносит ценность клиенту и обществу. Лидер, придерживающийся этого подхода, фокусируется на показателях, контроле выполнения задач и достижении поставленных целей. Для него важно — давать команде понятный смысл работы: мы создаём результат, который важен людям — нашим клиентам. Сильные стороны: - Ориентация на создание ценности для клиента и общества; - Быстрые и качественные решения в условиях неопределённости; - Умение удерживать фокус и выделять приоритеты - Ясность целей и измеримый результат. Как данный стиль влияет на человекоцентричную культуру в Компании: Ваш ведущий стиль формирует культуру ответственности за результат и осмысленной работы «не ради цифры, а ради пользы». Лидер транслирует связь задач команды с ценностью для клиента и общества, показывая, что особенно важно давать ясные ориентиры, понятные показатели, четкие планы и всегда синхронизироваться с тем, как то, что делает команда, будет приносить пользу Компании и клиентам. Ваш стиль человекоцентричности эффективен в ситуациях, если: - нужно быстро принять решение и сфокусировать команду на приоритетах в условиях неопределённости; - команде важно понять, как её работа создаёт ценность для клиента и общества, в том числе в долгосрочной перспективе; - в команде много задач/проектов и нужна ясность целей, сроков и измеримого результата; - возник риск нарушения сроков и нужно оперативно перераспределить нагрузку, сохраняя качество решений. Ваш стиль человекоцентричности менее эффективен в ситуациях, если: - нужно сфокусироваться на построении отношений и взаимопонимания внутри команды; - требуется пересмотр и упрощение бизнес-процессов; - команде необходимо выделить время и ресурс на индивидуальные траектории развития компетенций.
A5: Стиль "Вдохновляющий"
A6: Характеристика: Данный стиль ориентирован на развитие людей. Вектор в модели человекоцентричности-Лидер. Приоритеты — раскрытие потенциала, создание условий для роста, возможности для профессионального и личностного развития. Вдохновляющий лидер проявляет человекоцентричность через развитие и мотивацию других: он видит потенциал сотрудников, создаёт условия для обучения и роста, даёт амбициозные задачи и поддерживает траекторию развития. Сильные стороны: - Создание условий для раскрытия потенциала сотрудников; - Возможности для роста и обучения; - Мотивация через смысл и личный пример развития; - Формирование амбициозного видения «кем мы можем стать». Как данный стиль влияет на человекоцентричную культуру в Компании: Ваш ведущий стиль укрепляет культуру непрерывного развития и веры в потенциал людей. Лидер показывает, что Компания инвестирует в человека: даёт задачи для роста, обратную связь, наставничество. Вдохновляющий стиль наполняет работу команды пониманием своих возможностей для профессионального и карьерного роста. Ваш стиль человекоцентричности эффективен в ситуациях, если: - сотрудникам нужны задачи для роста, обратная связь и условия для раскрытия потенциала; - важен личный пример лидера и амбициозное видение; - формируется новая команда и нужно заложить культуру наставничества и развития; - необходимо создать пространство для обучения, освоения новых компетенций для профессионального/карьерного роста. Ваш стиль человекоцентричности менее эффективен в ситуациях, если: - жёсткие сроки и есть необходимость чёткого операционного контроля; - нужны прозрачные договорённости, роли и предсказуемость бизнес-процессов; - нужны системные правила и фокус на оптимизацию процессов.
A8: Стиль "Командный"
A9: Характеристика: Данный стиль ориентирован на команду и культуру взаимодействия. Вектор в модели человекоцентричности- Культура. Приоритеты — доброжелательное общение, уважительная коммуникация, культура взаимопомощи, ролевая модель корпоративной культуры. Командный лидер проявляет человекоцентричность через то, как команда общается и поддерживает друг друга: он демонстрирует уважительный диалог, тактичность и вежливость в общении, готовность помочь и быть опорой. Он — ролевая модель корпоративной культуры: показывает на своём примере, как принято общаться, договариваться и взаимодействовать в Компании. Сильные стороны: - Доброжелательная культура общения; - Уважительная коммуникация и конструктивная обратная связь; - Культура взаимопомощи и психологическая безопасность; - Ролевая модель корпоративных ценностей в ежедневном поведении. Как данный стиль влияет на человекоцентричную культуру в Компании: Ваш ведущий стиль задаёт «тон общения» в команде и вокруг неё: люди чувствуют, что их слышат, к ним относятся с уважением, можно просить помощи. Лидер укрепляет человекоцентричность через живое воплощение культуры Компании — не декларации, а ежедневные взаимодействия. Ваш стиль человекоцентричности эффективен в ситуациях, если: - команде важен уважительный диалог, тактичность и взаимопомощь; - важна роль медиатора и фасилитатора для достижения договоренностей; - необходимо адаптировать новых сотрудников, обеспечить комфортную среду, поддержку и «опору». Ваш стиль человекоцентричности менее эффективен в ситуациях, если: - нужно быстро принять непопулярное решение; - требуется достижение амбициозных результатов в короткие сроки, необходимо снять барьеры в процессах; - команде важен профессиональный вызов или внедрение инноваций.
A11: Стиль "Процессный"
A12: Характеристика: Данный стиль ориентирован на организацию работы. Вектор в модели человекоцентричности- Процессы и практики. Приоритеты — прозрачность, понятные договорённости, устранение барьеров, предсказуемость. Процессный лидер проявляет человекоцентричность через удобную и понятную среду работы: он выстраивает правила взаимодействия, убирает лишние препятствия и создаёт условия, в которых сотрудник может сосредоточиться на задаче. Основная цель — обеспечить максимальную эффективность через отлаженный и структурированный подход, делая акцент на том, чтобы процессы помогали людям, а не мешали им. Сильные стороны: - Прозрачность и предсказуемость работы; - Устранение организационных барьеров; - Оптимизация взаимодействий между людьми и подразделениями; - Снижение неопределённости «как договориться и что делать». Как данный стиль влияет на человекоцентричную культуру в Компании: Ваш ведущий стиль формирует культуру уважения к времени и усилиям людей: меньше хаоса, больше ясности. Лидер показывает, что человекоцентричность — это не бюрократия, а продуманная и организованная среда, где каждый понимает свою роль и может эффективно работать. Ваш стиль человекоцентричности эффективен в ситуациях, если: - команде нужны прозрачность и предсказуемость работы; - масштабируется типовая работа и важен понятный, воспроизводимый способ действий; - необходимо упрощение процессов и четкость ролей и зон ответственности. Ваш стиль человекоцентричности менее эффективен в ситуациях, если: - требуется фокус на инновации и эксперименты; - нужно сосредоточиться на построении доверительной атмосферы и взаимопонимания между сотрудниками; - команде не хватает мотивации и индивидуального подхода к развитию.

Sheet 3. Рекомендации по вед стилю 
A1: Как мне повывить человекоцентричность в моей команде
A2: Рекомендации по развитию, если ведущий стиль "Целеустременный" | B2: для системы, не выводим для пользователя
A3: Предлагаем вам расширить набор инструментов лидера : оставить фокус на создании ценности для клиента и Общества, но укрепить команду через понимание людей, их мотивации, раскрытия потенциала, усиление эффективности процессов. Для этого: Узнайте больше о своей команде: • Проведите индивидуальные беседы: понимает ли каждый сотрудник, как его работа влияет на клиента и общество, или видит только внутренние показатели. • Спросите, где темп решений и многозадачность помогают, а где создают перегруз и снижают качество. • Соберите обратную связь: достаточно ли в команде уважительного общения и взаимопомощи, а также условий для роста. • Проанализируйте, где "размымость" ролей и лишние барьеры мешают людям достигать результата. Внедряйте в практику и делайте чаще: • В начале задач формулируйте связку: «Для кого мы это делаем: клиент, общество, команда» — не только KPI. • На командных встречах совмещайте приоритеты и решения с тем, как команда помогает друг другу. • Давайте сотрудникам задачи на развитие и обратную связь о росте, а не только о цифрах. • Упрощайте согласования и убирайте лишние шаги на пути к результату. • Признавайте личный вклад сотрудников в ценность для клиента, а не только выполнение плана. Закрепите изменения и дополните свой стиль: • Развивайте культуру уважительной обратной связи — результат не отменяет важность отношений. • Обсудите вместе с сотрудниками их индивидуальные траектории развития компетенций: в чем их сильные стороны, а какие навыки можно усилить. • Регулярно пересматривайте «узкие места» процессов, которые мешают людям работать эффективно. | B3: дополнить для усиления, чтобы из характеристик других стилей были рекомендации Коллеги, может быть 1-2 практикума еще рекомендуем на каждый стиль?
A5: Рекомендации по развитию стиля "Вдохновляющий" | B5: для системы, не выводим для пользователя
A6: Предлагаем вам расширить набор инструментов лидера: сохранить фокус на драйве и энергии лидера, его стремлении развивать команду, но усилить управляемость через цели, контрольные точки и ясные бизнес-механизмы, а также фокус на создании команды как единого целого для более долгосрочного сотрудничества. Для этого: Узнайте больше о своей команде: • Составьте карту потенциала: кому нужен вызов, кому — поддержка, кому — структура, кому — больше времени на обучение. • Уточните, видят ли сотрудники связь между их ростом и ценностью для клиента и общества. • Проверьте, есть ли понятные договорённости о целях, сроках и критериях успеха. • Спросите, достаточно ли текущего уровня общения в команде — норма, которую вы поддерживаете, комфортно ли сотрудникам работать в команде. Внедряйте в практику и делайте чаще: • Обсудите с сотрудниками их индивидуальные траектории развития: в чем их сильные стороны, а какие навыки можно усилить. • Связывайте задачи на рост с реальной пользой для клиента и общества. • Фиксируйте контрольные точки и критерии успеха по проектам. • Делегируйте полномочия, а не только задачи. • Проводите регулярную обратную связь о прогрессе развития. Закрепите изменения и дополните свой стиль: • Закрепите правило: «Развитие = задача + поддержка + измеримый результат». • Раз в квартал обсуждайте: как наш рост влияет на клиента и общество. • Упростите правила взаимодействия там, где неясность мешает людям расти. • Поддерживайте уважительный и доброжелательный тон общения в команде.
A8: Рекомендации по развитию стиля "Командный" | B8: для системы, не выводим для пользователя
A9: Предлагаем вам расширить набор инструментов лидера: сохранить фокус на команде и взаимоотношениях, но усилить управляемость через ясные роли, измеримые договоренности и контроль прогресса. Для этого: 1. Узнайте больше о своей команде: • Спросите, понимает ли команда, какую ценность для клиента и общества создаёт их работа • Проверьте, зафиксированы ли договорённости о ролях, сроках и ответственности • Уточните, прозрачны и ясны ли для команды цели и процессы 2. Внедряйте в практику и делайте чаще: • Продолжайте совершенствовать командные правила взаимодействия, например, о том, как даём обратную связь, как спорим, как просим помощи. • На встречах больше обсуждайте, «какую ценность для клиента мы создаём». • Фиксируйте решения письменно: кто, что, к какому сроку выполняет. • В сложных ситуациях практикуйте не только уважительный, но и прямой разговор. • Обозначайте личную ответственность сотрудников 3. Скорректируйте/ Закрепите изменения и дополните свой стиль: • Закрепите норму: «Мы уважительны — и мы доводим до результата». • Всегда сверяйтесь: создали ли ценность для клиента и общества. • Упростите лишние согласования. • Введите в свою практику содействие сотрудникам в выборе вектора развития и формировании траектории развития.
A11: Рекомендации по развитию стиля "Процессный" | B11: для системы, не выводим для пользователя
A12: Предлагаем вам расширить набор инструментов лидера: сохранить фокус на процессах и эффективности, но усилить управляемость через создание доброжелательной и уважительной среды в команде, мотивацию, делегирование и развитие людей. Для этого: 1. Узнайте больше о своей команде: • Соберите обратную связь, где процессы реально помогают, а где создают «трение». • Выясните, видит ли команда связь работы с ценностью для клиента и общества. • Оцените, достаточно ли уважительного общения и взаимопомощи. • Узнайте, известны ли сотрудникам их возможности для роста, раскрывают ли они свой потенциал. 2. Внедряйте в практику и делайте чаще: • Пересматривайте процессы: «Минимум правил — максимум ясности». • При описании задач добавляйте, зачем это клиенту и обществу. • Вовлекайте команду в совместное упрощение процессов. • Поддерживайте уважительное общение в команде. • Давайте задачи на развитие сотрудников, помогайте им усиливать свои компетенции. • В нестандартных ситуациях используйте пилоты и эксперименты. 3. Скорректируйте/ Закрепите изменения и дополните свой стиль: • Закрепите правило: «Процесс служит человеку — не наоборот». • Развивайте культуру, в которой сотрудник не боится допускать ошибки. • Связывайте изменения процессов с ценностью для клиента. • Развивайте взаимопомощь и поддержку в команде. • Поддерживайте индивидуальное развитие компетенций.

Sheet 4.Рекомендации по слаб стилю
B1: Отчет по тесту «Определение ведущего стиля человекоцентричного лидерства» | J1: Стиль | K1: Баллы
J2: Целеустремленный | K2: ='Механика подсчета результатов'!R2 -> 34
B3: Блок 1. Описание об отчёте и об инструменте | J3: Вдохновляющий | K3: ='Механика подсчета результатов'!S2 -> 16
B4: ='1. Вводная часть отчета'!B2 -> 0 | J4: Командный | K4: ='Механика подсчета результатов'!T2 -> 14
J5: Процессный | K5: ='Механика подсчета результатов'!U2 -> 34
B9: ='1. Вводная часть отчета'!B4 -> 0
B15: Блок 2. Ваши результаты
B16: 🎯 Целеустремленный
B17: ✨ Вдохновляющий
B18: 🤝 Командный
B19: ⚙️ Процессный
B30: ="Ваш ведущий стиль человекоцентричного лидерства — "&'Механика подсчета результатов'!S20&" ("&'Механика подсчета результатов'!S21&" баллов из 98)" -> Ваш ведущий стиль человекоцентричного лидерства — Целеустремленный (34 баллов из 98)
B32: =IF('Механика подсчета результатов'!S20="Командный",#REF!, IF( 'Механика подсчета результатов'!S20="Целеустремленный",#REF!, IF( 'Механика подсчета результатов'!S20="Вдохновляющий",#REF!, IF( 'Механика подсчета результатов'!S20="Процессный",#REF!, "")))) -> #REF!
B42: Блок 3. Познакомьтесь с другими стилями человекоцентричного лидерства
B43: Краткие характеристики ниже. Полное описание раскрывается кнопкой + слева от сгруппированных строк.
B45: 🎯 Целеустремленный
B46: =#REF! -> #REF!
G49: ▼ Подробнее
B50: ✨ Вдохновляющий
B51: =#REF! -> #REF!
G54: ▼ Подробнее
B55: 🤝 Командный
B56: =#REF! -> #REF!
G59: ▼ Подробнее
B60: ⚙️ Процессный
B61: =#REF! -> #REF!
G64: ▼ Подробнее
B65: =#REF! -> #REF!
B73: =#REF! -> #REF!
B81: =#REF! -> #REF!
B89: =#REF! -> #REF!
B110: Блок 4. Рекомендации по развитию вашего ведущего стиля
B111: =IF('Механика подсчета результатов'!S20="Командный", '3. Рекомендации по вед стилю '!B9, IF('Механика подсчета результатов'!S20="Целеустремленный", '3. Рекомендации по вед стилю '!B3, IF('Механика подсчета результатов'!S20="Вдохновляющий", '3. Рекомендации по вед стилю '!B6, IF('Механика подсчета результатов'!S20="Процессный", '3. Рекомендации по вед стилю '!B12, "")))) -> дополнить для усиления, чтобы из характеристик других стилей были рекомендации Коллеги, может быть 1-2 практикума еще рекомендуем на каждый стиль?

Sheet 4.Прототип отчета
B1: Отчёт по тесту «Определение ведущего стиля человекоцентричного лидерства» | N1: Стиль | O1: Баллы
N2: Целеустремленный | O2: ='Механика подсчета результатов'!R2 -> 34
N3: Вдохновляющий | O3: ='Механика подсчета результатов'!S2 -> 16
B4: Об отчёте | N4: Командный | O4: ='Механика подсчета результатов'!T2 -> 14
B5: ='1. Вводная часть отчета'!A2 -> Поздравляем вас с завершением теста! Теперь можно познакомиться с результатами. Данный отчет отображает результаты, полученные при прохождении теста. Тест предназначен для определения ведущего стиля, с помощью которого вы проявляете человеокцентричность. Цель отчета- выявить ваш наиболее предпочитаемый стиль и дать рекомендации по усилению человекоцентричной культуры в вашей команде. Персональный отчет состоит из нескольких блоков: -Введение -Ваши результаты -Характеристика других стилей -Рекомендации по развитию вашего стиля человекоцентричного лидерства | N5: Процессный | O5: ='Механика подсчета результатов'!U2 -> 34
B13: Об инструменте
B14: ='1. Вводная часть отчета'!A4 -> Инструмент диагностики "Тест на определение ведущего стиля человекоцентричного лидерства" создан на основе: - Модели "Человекоцентричного лидерства в Ростелекоме", - Модели Р.Лайкерта "Фокус на людей"- "Фокус на задачи", - Теории цикла командного взаимодействия. Что такое человекоцентричное лидерство? - Это подход в управлении, где центром является человек: клиент, подчиненный, коллега, руководитель-все, с кем взаимодействует лидер в организации. Модель ЧЛ опирается на четыре вектора: Культура, Лидер, Процессы и практики, Стратегия. Каждому вектору соответствует определенный стиль. Важно: данный тест не направлен на выявление целегового или желательного уровня\индекса человекоцентричности. Он способствует понимаю лидера особенностей своего стиля, а также ситуаций, в которых данный стиль будет предпочтителен, а где стоит применять другие подходы.
B24: Ваши результаты
B25: 🎯 Целеустремленный | D25: ✨ Вдохновляющий | F25: 🤝 Командный | H25: ⚙️ Процессный
B26: ='Механика подсчета результатов'!R2 -> 34 | D26: ='Механика подсчета результатов'!S2 -> 16 | F26: ='Механика подсчета результатов'!T2 -> 14 | H26: ='Механика подсчета результатов'!U2 -> 34
B27: баллов | D27: баллов | F27: баллов | H27: баллов
B29: ="🏆 Ваш ведущий стиль: "&'Механика подсчета результатов'!S20&" ("&'Механика подсчета результатов'!S21&" баллов)" -> 🏆 Ваш ведущий стиль: Целеустремленный (34 баллов)
M31: надо секторную диаграмму, он не делает в эксель, сделаем в другом формате
B32: Описание вашего ведущего стиля
B33: =CHOOSE('Механика подсчета результатов'!V2, '2. Харак-ка стилей'!A3, '2. Харак-ка стилей'!A6, '2. Харак-ка стилей'!A9, '2. Харак-ка стилей'!A12) -> Характеристика: Данный стиль ориентирован на результат и создание ценности для клиентов. Вектор в модели человекоцентричности- Стратегия. Приоритеты — цели, достижения, своевременные решения, создание ценности для клиента и общества. Целеустремлённый лидер проявляет человекоцентричность через ясность целей и достижение результата, который приносит ценность клиенту и обществу. Лидер, придерживающийся этого подхода, фокусируется на показателях, контроле выполнения задач и достижении поставленных целей. Для него важно — давать команде понятный смысл работы: мы создаём результат, который важен людям — нашим клиентам. Сильные стороны: - Ориентация на создание ценности для клиента и общества; - Быстрые и качественные решения в условиях неопределённости; - Умение удерживать фокус и выделять приоритеты - Ясность целей и измеримый результат. Как данный стиль влияет на человекоцентричную культуру в Компании: Ваш ведущий стиль формирует культуру ответственности за результат и осмысленной работы «не ради цифры, а ради пользы». Лидер транслирует связь задач команды с ценностью для клиента и общества, показывая, что особенно важно давать ясные ориентиры, понятные показатели, четкие планы и всегда синхронизироваться с тем, как то, что делает команда, будет приносить пользу Компании и клиентам. Ваш стиль человекоцентричности эффективен в ситуациях, если: - нужно быстро принять решение и сфокусировать команду на приоритетах в условиях неопределённости; - команде важно понять, как её работа создаёт ценность для клиента и общества, в том числе в долгосрочной перспективе; - в команде много задач/проектов и нужна ясность целей, сроков и измеримого результата; - возник риск нарушения сроков и нужно оперативно перераспределить нагрузку, сохраняя качество решений. Ваш стиль человекоцентричности менее эффективен в ситуациях, если: - нужно сфокусироваться на построении отношений и взаимопонимания внутри команды; - требуется пересмотр и упрощение бизнес-процессов; - команде необходимо выделить время и ресурс на индивидуальные траектории развития компетенций.
B50: Ознакомьтесь с описанием других стилей
B51: Ниже — характеристики трёх стилей, отличных от вашего ведущего. Нажмите ссылку «Полное описание стиля» — откроется лист с характеристиками.
B53: =INDEX('2. Харак-ка стилей'!A:A, CHOOSE('Механика подсчета результатов'!V2, 6, 3, 3, 3)-1) -> Стиль "Вдохновляющий"
B54: =LEFT(INDEX('2. Харак-ка стилей'!A:A, CHOOSE('Механика подсчета результатов'!V2, 6, 3, 3, 3)), IFERROR(FIND("Сильные стороны", INDEX('2. Харак-ка стилей'!A:A, CHOOSE('Механика подсчета результатов'!V2, 6, 3, 3, 3)))-1, LEN(INDEX('2. Харак-ка стилей'!A:A, CHOOSE('Механика подсчета результатов'!V2, 6, 3, 3, 3))))) -> Характеристика: Данный стиль ориентирован на развитие людей. Вектор в модели человекоцентричности-Лидер. Приоритеты — раскрытие потенциала, создание условий для роста, возможности для профессионального и личностного развития. Вдохновляющий лидер проявляет человекоцентричность через развитие и мотивацию других: он видит потенциал сотрудников, создаёт условия для обучения и роста, даёт амбициозные задачи и поддерживает траекторию развития.
B59: =HYPERLINK("#'2. Харак-ка стилей'!A"&CHOOSE('Механика подсчета результатов'!V2, 6, 3, 3, 3), "▶ Полное описание стиля") -> ▶ Полное описание стиля
B64: =INDEX('2. Харак-ка стилей'!A:A, CHOOSE('Механика подсчета результатов'!V2, 9, 9, 6, 6)-1) -> Стиль "Командный"
B65: =LEFT(INDEX('2. Харак-ка стилей'!A:A, CHOOSE('Механика подсчета результатов'!V2, 9, 9, 6, 6)), IFERROR(FIND("Сильные стороны", INDEX('2. Харак-ка стилей'!A:A, CHOOSE('Механика подсчета результатов'!V2, 9, 9, 6, 6)))-1, LEN(INDEX('2. Харак-ка стилей'!A:A, CHOOSE('Механика подсчета результатов'!V2, 9, 9, 6, 6))))) -> Характеристика: Данный стиль ориентирован на команду и культуру взаимодействия. Вектор в модели человекоцентричности- Культура. Приоритеты — доброжелательное общение, уважительная коммуникация, культура взаимопомощи, ролевая модель корпоративной культуры. Командный лидер проявляет человекоцентричность через то, как команда общается и поддерживает друг друга: он демонстрирует уважительный диалог, тактичность и вежливость в общении, готовность помочь и быть опорой. Он — ролевая модель корпоративной культуры: показывает на своём примере, как принято общаться, договариваться и взаимодействовать в Компании.
B70: =HYPERLINK("#'2. Харак-ка стилей'!A"&CHOOSE('Механика подсчета результатов'!V2, 9, 9, 6, 6), "▶ Полное описание стиля") -> ▶ Полное описание стиля
B75: =INDEX('2. Харак-ка стилей'!A:A, CHOOSE('Механика подсчета результатов'!V2, 12, 12, 12, 9)-1) -> Стиль "Процессный"
B76: =LEFT(INDEX('2. Харак-ка стилей'!A:A, CHOOSE('Механика подсчета результатов'!V2, 12, 12, 12, 9)), IFERROR(FIND("Сильные стороны", INDEX('2. Харак-ка стилей'!A:A, CHOOSE('Механика подсчета результатов'!V2, 12, 12, 12, 9)))-1, LEN(INDEX('2. Харак-ка стилей'!A:A, CHOOSE('Механика подсчета результатов'!V2, 12, 12, 12, 9))))) -> Характеристика: Данный стиль ориентирован на организацию работы. Вектор в модели человекоцентричности- Процессы и практики. Приоритеты — прозрачность, понятные договорённости, устранение барьеров, предсказуемость. Процессный лидер проявляет человекоцентричность через удобную и понятную среду работы: он выстраивает правила взаимодействия, убирает лишние препятствия и создаёт условия, в которых сотрудник может сосредоточиться на задаче. Основная цель — обеспечить максимальную эффективность через отлаженный и структурированный подход, делая акцент на том, чтобы процессы помогали людям, а не мешали им.
B81: =HYPERLINK("#'2. Харак-ка стилей'!A"&CHOOSE('Механика подсчета результатов'!V2, 12, 12, 12, 9), "▶ Полное описание стиля") -> ▶ Полное описание стиля
B88: Как мне повысить человекоцентричность в моей команде?
B89: =CHOOSE('Механика подсчета результатов'!V2, '3. Рекомендации по вед стилю '!A3, '3. Рекомендации по вед стилю '!A6, '3. Рекомендации по вед стилю '!A9, '3. Рекомендации по вед стилю '!A12) -> Предлагаем вам расширить набор инструментов лидера : оставить фокус на создании ценности для клиента и Общества, но укрепить команду через понимание людей, их мотивации, раскрытия потенциала, усиление эффективности процессов. Для этого: Узнайте больше о своей команде: • Проведите индивидуальные беседы: понимает ли каждый сотрудник, как его работа влияет на клиента и общество, или видит только внутренние показатели. • Спросите, где темп решений и многозадачность помогают, а где создают перегруз и снижают качество. • Соберите обратную связь: достаточно ли в команде уважительного общения и взаимопомощи, а также условий для роста. • Проанализируйте, где "размымость" ролей и лишние барьеры мешают людям достигать результата. Внедряйте в практику и делайте чаще: • В начале задач формулируйте связку: «Для кого мы это делаем: клиент, общество, команда» — не только KPI. • На командных встречах совмещайте приоритеты и решения с тем, как команда помогает друг другу. • Давайте сотрудникам задачи на развитие и обратную связь о росте, а не только о цифрах. • Упрощайте согласования и убирайте лишние шаги на пути к результату. • Признавайте личный вклад сотрудников в ценность для клиента, а не только выполнение плана. Закрепите изменения и дополните свой стиль: • Развивайте культуру уважительной обратной связи — результат не отменяет важность отношений. • Обсудите вместе с сотрудниками их индивидуальные траектории развития компетенций: в чем их сильные стороны, а какие навыки можно усилить. • Регулярно пересматривайте «узкие места» процессов, которые мешают людям работать эффективно.

Sheet Справка
A1: 1. Блок 1: Источник ценности (Вклад) | Z1: 1
Z2: 2
A3: Задача: Определить «точку входа». Что человек приносит в команду в момент создания проекта? | Z3: 3
A4: Смысл: Здесь выявляется, какой ресурс вы даете первым. Это «аванс» команды. Кто-то заходит с идеями, кто-то с организаторскими способностями, а кто-то — с готовностью работать «в полях». | Z4: 4
Z5: 5
A6: 2. Блок 2: Оборотная сторона медали (Слабости / Ограничения) | Z6: 6
Z7: 7
A8: Задача: Осознать «теневую сторону». У каждой сильной стороны есть цена.
A9: Смысл: Белбин утверждал, что у каждого специалиста есть «допустимые слабости». Этот блок показывает: чем вы готовы пожертвовать, чтобы ваша главная роль проявилась? Например, если вы гениальный «Мыслитель», вы можете быть рассеянным. Без признания этой слабости команда не сможет вас «подстраховать».
A11: 3. Блок 3: Интеграция (Взаимодействие с коллегами)
A13: Задача: Понять стиль «стыковки» с другими. Как вы встраиваетесь в текущую структуру?
A14: Смысл: Работа команды – это всегда трение. Этот блок показывает, являетесь ли вы тем, кто сглаживает углы, или тем, кто эти углы создает для прогресса. Это про стиль коммуникации «здесь и сейчас».
A16: 4. Блок 4: Рабочий стиль (Поведение в процессе)
A18: Задача: Описать ваши механизмы достижения целей.
A19: Смысл: Это «operational mode». Когда проект запущен, как вы лично его ведете? Вы следуете методологии? Ищете креативные обходные пути? Или просто давите авторитетом, чтобы работа была сделана? Здесь проверяется ваша операционная эффективность.
A21: 5. Блок 5: Мотивация (Внутренние стимулы)
A23: Задача: Определить, что вас «заряжает» в командной игре.
A24: Смысл: Команда может буксовать. Этот блок выявляет, что заставляет вас не бросить дело на полпути. Для одних это признание, для других — новизна задачи, для третьих — достижение конкретного результата. Это показатель «выносливости» вашего участия в цикле.
A26: 6. Блок 6: Отношение к другим (Реакция на вклад партнеров)
... A34: Смысл: Много команд отлично начинают, но не доводят дело до конца. Этот блок выявляет, есть ли у вас «финишная черта». Вы склонны доводить проект до идеала, бросать его как только смысл стал понятен, или постоянно проверять его на ошибки (контроль качества)?
